Traceback (most recent call last):
  File "D:\Python_projects\AvitoRU_SileniumWebScraping\venv\lib\site-packages\urllib3\connection.py", line 174, in _new_conn
    conn = connection.create_connection(
  File "D:\Python_projects\AvitoRU_SileniumWebScraping\venv\lib\site-packages\urllib3\util\connection.py", line 95, in create_connection
    raise err
  File "D:\Python_projects\AvitoRU_SileniumWebScraping\venv\lib\site-packages\urllib3\util\connection.py", line 85, in create_connection
    sock.connect(sa)
ConnectionRefusedError: [WinError 10061] Подключение не установлено, т.к. конечный компьютер отверг запрос на подключение

During handling of the above exception, another exception occurred:

Traceback (most recent call last):
  File "D:\Python_projects\AvitoRU_SileniumWebScraping\venv\lib\site-packages\urllib3\connectionpool.py", line 703, in urlopen
    httplib_response = self._make_request(
  File "D:\Python_projects\AvitoRU_SileniumWebScraping\venv\lib\site-packages\urllib3\connectionpool.py", line 398, in _make_request
    conn.request(method, url, **httplib_request_kw)
  File "D:\Python_projects\AvitoRU_SileniumWebScraping\venv\lib\site-packages\urllib3\connection.py", line 239, in request
    super(HTTPConnection, self).request(method, url, body=body, headers=headers)
  File "C:\Users\Kostyan\AppData\Local\Programs\Python\Python38\lib\http\client.py", line 1252, in request
    self._send_request(method, url, body, headers, encode_chunked)
  File "C:\Users\Kostyan\AppData\Local\Programs\Python\Python38\lib\http\client.py", line 1298, in _send_request
    self.endheaders(body, encode_chunked=encode_chunked)
  File "C:\Users\Kostyan\AppData\Local\Programs\Python\Python38\lib\http\client.py", line 1247, in endheaders
    self._send_output(message_body, encode_chunked=encode_chunked)
  File "C:\Users\Kostyan\AppData\Local\Programs\Python\Python38\lib\http\client.py", line 1007, in _send_output
    self.send(msg)
  File "C:\Users\Kostyan\AppData\Local\Programs\Python\Python38\lib\http\client.py", line 947, in send
    self.connect()
  File "D:\Python_projects\AvitoRU_SileniumWebScraping\venv\lib\site-packages\urllib3\connection.py", line 205, in connect
    conn = self._new_conn()
  File "D:\Python_projects\AvitoRU_SileniumWebScraping\venv\lib\site-packages\urllib3\connection.py", line 186, in _new_conn
    raise NewConnectionError(
urllib3.exceptions.NewConnectionError: <urllib3.connection.HTTPConnection object at 0x0000000004F95310>: Failed to establish a new connection: [WinError 10061] Подключение не установлено, т.к. конечный компьютер отверг запрос на подключение

During handling of the above exception, another exception occurred:

Traceback (most recent call last):
  File "D:/Python_projects/AvitoRU_SileniumWebScraping/main.py", line 70, in <module>
    current_url = run_process(URL, current_page, output_filename)
  File "D:/Python_projects/AvitoRU_SileniumWebScraping/main.py", line 51, in run_process
    current_url = browser.current_url
  File "D:\Python_projects\AvitoRU_SileniumWebScraping\venv\lib\site-packages\selenium\webdriver\remote\webdriver.py", line 528, in current_url
    return self.execute(Command.GET_CURRENT_URL)['value']
  File "D:\Python_projects\AvitoRU_SileniumWebScraping\venv\lib\site-packages\selenium\webdriver\remote\webdriver.py", line 432, in execute
    response = self.command_executor.execute(driver_command, params)
  File "D:\Python_projects\AvitoRU_SileniumWebScraping\venv\lib\site-packages\selenium\webdriver\remote\remote_connection.py", line 344, in execute
    return self._request(command_info[0], url, body=data)
  File "D:\Python_projects\AvitoRU_SileniumWebScraping\venv\lib\site-packages\selenium\webdriver\remote\remote_connection.py", line 366, in _request
    response = self._conn.request(method, url, body=body, headers=headers)
  File "D:\Python_projects\AvitoRU_SileniumWebScraping\venv\lib\site-packages\urllib3\request.py", line 74, in request
    return self.request_encode_url(
  File "D:\Python_projects\AvitoRU_SileniumWebScraping\venv\lib\site-packages\urllib3\request.py", line 96, in request_encode_url
    return self.urlopen(method, url, **extra_kw)
  File "D:\Python_projects\AvitoRU_SileniumWebScraping\venv\lib\site-packages\urllib3\poolmanager.py", line 376, in urlopen
    response = conn.urlopen(method, u.request_uri, **kw)
  File "D:\Python_projects\AvitoRU_SileniumWebScraping\venv\lib\site-packages\urllib3\connectionpool.py", line 815, in urlopen
    return self.urlopen(
  File "D:\Python_projects\AvitoRU_SileniumWebScraping\venv\lib\site-packages\urllib3\connectionpool.py", line 815, in urlopen
    return self.urlopen(
  File "D:\Python_projects\AvitoRU_SileniumWebScraping\venv\lib\site-packages\urllib3\connectionpool.py", line 815, in urlopen
    return self.urlopen(
  File "D:\Python_projects\AvitoRU_SileniumWebScraping\venv\lib\site-packages\urllib3\connectionpool.py", line 787, in urlopen
    retries = retries.increment(
  File "D:\Python_projects\AvitoRU_SileniumWebScraping\venv\lib\site-packages\urllib3\util\retry.py", line 592, in increment
    raise MaxRetryError(_pool, url, error or ResponseError(cause))
urllib3.exceptions.MaxRetryError: HTTPConnectionPool(host='localhost', port=49448): Max retries exceeded with url: /session/f67f5a1f-ea99-4047-bdba-2960c464bc83/url (Caused by NewConnectionError('<urllib3.connection.HTTPConnection object at 0x0000000004F95310>: Failed to establish a new connection: [WinError 10061] Подключение не установлено, т.к. конечный компьютер отверг запрос на подключение'))